Workbook

Sheet MOVI
A1: No. | B1: ID | C1: Mã nhân viên mới | D1: Full Name | E1: Department | F1: Business Unit | G1: Internal Job Band | H1: Current Job Title | I1: Region | J1: Company | K1: Type of Employee | L1: Employment Status | M1: Joining Date | N1: Matenity Leaving Date | O1: Unpaid | P1: Effective Leaving Date | Q1: Type of contract | U1: Contract salary | X1: ALLOWANCE | AE1: Time Attendance | AL1: Over times | AR1: Actual Gross Salary | AU1: Total Actual Gross Salary | AV1: Actual Allowance | BF1: Total Actual Allowance | BG1: INCENTIVE/BONUS | BT1: Total Bonus/ Incentive | BU1: TOTAL INCOME | BV1: Tax relief | CB1: 0.08 | CC1: 0.01 | CD1: 0.015 | CE1: 0.045 | CF1: Total SMU | CG1: Total Tax Relief | CH1: PIT | CL1: Severance Allow Payment/Net adjustments | CM1: Net Deduction | CR1: Total Net Deduction | CS1: INCOME | CV1: 0.17 | CW1: 0 | CX1: 0.03 | CY1: 0 | CZ1: 0.045 | DA1: 21.0% by ER | DB1: 0.305 | DC1: 0.02
Q2: JO/ LC/ SC | R2: TYPE OF PIT | S2: E/L | T2: Count days for Expat | U2: Basic Salary | V2: KPI salary | W2: Total Contract Salary | X2: Laptop | Y2: Transportation | Z2: Position | AA2: Phone | AB2: Housing | AC2: Meal Allowance | AD2: Total Allowance | AE2: Standard weekly | AF2: Standard WK Days | AG2: Actual WK Days | AH2: Annual Leave days | AI2: Public Holidays | AJ2: Other Paid leave | AK2: Total Actual WK Days | AL2: Standard Nomal day | AM2: Weekend | AN2: Public Holiday | AO2: Total OT hours | AP2: Total OT hours x rating OT | AQ2: Nontaxable - Total OT hous x rating OT | AR2: Actual Gross Salary | AS2: Other adjustment (+/-) | AT2: OT Payment | AV2: Laptop | AW2: Transportation | AX2: Position | AY2: Phone | AZ2: Gasoline | BA2: Housing | BB2: Training | BC2: Public Holiday | BD2: Special Allowance | BE2: Meal Allowance | BG2: Incentive for FL & TLS | BH2: Bonus for FL & TLS | BI2: Candidate referral bonus | BJ2: Debt collection | BK2: MKT Bonus | BL2: MA/MD Bonus | BM2: Delivery Bonus | BN2: B2B Bonus | BO2: CS Bonus | BP2: Logistics Bonus | BQ2: 13th Bonus | BR2: Bonus paid by region/ Benefit - in -kind or pay out cash | BS2: Engagement Program Bonus | BV2: OT-nontaxable | BW2: Phone | BX2: Meal - Non tax | BY2: Personal Deduction | BZ2: No.of Dedendants | CA2: Deduction of Dependants | CB2: SI | CC2: UI | CD2: HI | CE2: Special case | CH2: Taxed Income | CI2: PIT in month | CJ2: PIT Finalization/ Adjusment (-return/+collect) 2020 | CK2: PIT payable | CM2: Trade Union Fee | CN2: Cash advance | CO2: Mobilephone | CP2: MCA Amount | CQ2: Other Deduction | CS2: NET INCOME | CT2: PAID | CU2: BANK TRANSFER TO EE (NTH>0) | CV2: SI | CW2: UI | CX2: HI | CY2: ADI | CZ2: Special case | DA2: SI+HI+UI+ADI | DB2: Total SMU | DC2: Trade Union (2%) | DD2: GRAND TOTAL COMPANY COST | DE2: NOTE | DF2: for C&B Report | DG2: 13rd Bonus Budget | DH2: Area | DI2: Total WD 1st - 25th | DJ2: For SMU | DK2: Total Unpaid Leave for SHUI | DL2: List of union staff | DM2: Laptop | DN2: Trade Union Fee (employee) | DO2: Days of Phone Allowance | DP2: Area for report (Revenue South) | DQ2: Maternity from | DR2: Maternity to | DS2: Group | DT2: for Expense Report (Group)
A3: # | B3: 1 | C3: 1 | D3: 2 | E3: 3 | F3: =+E3+1 -> 4 | G3: =+F3+1 -> 5 | H3: =+G3+1 -> 6 | I3: =+H3+1 -> 7 | J3: =+I3+1 -> 8 | K3: =+J3+1 -> 9 | L3: =+K3+1 -> 10 | M3: =+L3+1 -> 11 | ... CA3: =+BZ3+1 -> 77 | CB3: 78 | CC3: 79 | CD3: 80 | CE3: 81 | CF3: 82 | CG3: 83 | CH3: 84 | CI3: 85 | CJ3: 86 | CK3: 87 | CL3: =+CK3+1 -> 88 | CM3: =+CL3+1 -> 89 | CN3: =+CM3+1 -> 90 | CO3: =+CN3+1 -> 91 | CP3: 92 | CQ3: =+CP3+1 -> 93 | CR3: =+CQ3+1 -> 94 | CS3: =+CR3+1 -> 95 | CT3: =+CS3+1 -> 96 | CU3: =+CT3+1 -> 97 | CV3: 98 | CW3: 99 | CX3: 100 | CY3: 101 | CZ3: 102 | DA3: 103 | DB3: 104 | DC3: =+DB3+1 -> 105 | DD3: =+DC3+1 -> 106 | DE3: =+DD3+1 -> 107 | DF3: =+DE3+1 -> 108 | DG3: =+DF3+1 -> 109 | DH3: =+DG3+1 -> 110 | DI3: =+DH3+1 -> 111 | DJ3: =+DI3+1 -> 112 | ... DT3: =+DS3+1 -> 122
A4: 1 | B4: 5031 | C4: VP005031 | D4: Trần Quốc Huy | E4: Finance | F4: Accounting & Tax | G4: Manager | H4: Chief Accountant | I4: South | J4: Việt Phú | K4: Full-time | L4: Permanent | M4: 43591 | Q4: LC | R4: LTTP | S4: L | U4: 40000000 | W4: 40000000 | X4: 0 | Y4: 0 | AA4: 0 | AC4: 0 | AD4: 0 | AE4: TB, CN | AF4: 21 | AG4: 21 | AH4: 0 | AI4: 0 | AJ4: 0 | AK4: 21 | AL4: 0 | AM4: 0 | AN4: 0 | AO4: 0 | AP4: 0 | AQ4: 0 | AR4: 40000000 | AS4: 0 | AT4: 0 | AU4: 40000000 | AV4: 0 | AW4: 0 | AX4: 0 | AY4: 0 | AZ4: 0 | BA4: 0 | BE4: 0 | BF4: 0 | BG4: 0 | BH4: 0 | BI4: 0 | BJ4: 0 | BL4: 0 | BO4: 0 | BT4: 0 | BU4: 40000000 | BV4: 0 | BW4: 0 | BX4: 0 | BY4: 11000000 | BZ4: 2 | CA4: 8800000 | CB4: 2384000 | CC4: 400000 | CD4: 447000 | CE4: 0 | CF4: 3231000 | CG4: 23031000 | CH4: 16969000 | CI4: 1795350 | CK4: 1795350 | CL4: 0 | CM4: 0 | CN4: 0 | CP4: 0 | CQ4: 0 | CR4: 0 | CS4: 34973650 | CU4: 34973650 | CV4: 5066000 | CW4: 0 | CX4: 894000 | CY4: 0 | DA4: 5960000 | DB4: 9191000 | DC4: 596000 | DD4: 46556000 | DF4: Việt PhúSouthFinance | DG4: 3333333.3 | DH4: HO | DI4: =IFERROR(VLOOKUP($B4,[1]Timesheet!$D:$BK,51,0),0) -> 18 | DJ4: =IFERROR(VLOOKUP($B4,[1]Timesheet!$D:$BK,52,0),0) -> 0 | DK4: =IFERROR(VLOOKUP($B4,[1]Timesheet!$D:$BK,55,0),0) -> 0 | DL4: 0 | DM4: =IFERROR(VLOOKUP($B4,[1]Timesheet!$D:$BK,57,0),0) -> 0 | DN4: =IF(AND(DL4="x",CB4>0),MIN(ROUND(W4*1%,0),149000),0) -> 0 | DP4: =IF(E4="Sales",IF(F4="Logistics",F4,IF(F4="Marketing",F4,DH4)),"") | DQ4: 0 | DR4: 0 | DS4: =IFERROR(VLOOKUP(E4&H4,[1]Group!$D$3:$G$40,4,0),"") | DT4: =J4&I4&DS4 -> Việt PhúSouth
A5: 2 | B5: 2210 | C5: VP002210 | D5: Dương Thị Kim Phố | E5: Finance | F5: Accounting & Tax | G5: Senior Associate | H5: General Accountant | I5: South | J5: Việt Phú | K5: Full-time | L5: Permanent | M5: 41939 | Q5: LC | R5: LTTP | S5: L | U5: 10000000 | W5: 10000000 | X5: 0 | Y5: 0 | AA5: 0 | AC5: 0 | AD5: 0 | AE5: TB, CN | AF5: 21 | AG5: 21 | AH5: 0 | AI5: 0 | AJ5: 0 | AK5: 21 | AL5: 0 | AM5: 0 | AN5: 0 | AO5: 0 | AP5: 0 | AQ5: 0 | AR5: 10000000 | AS5: 0 | AT5: 0 | AU5: 10000000 | AV5: 0 | AW5: 0 | AX5: 0 | AY5: 0 | AZ5: 0 | BA5: 0 | BE5: 0 | BF5: 0 | BG5: 0 | BH5: 0 | BI5: 0 | BJ5: 0 | BL5: 0 | BO5: 0 | BT5: 0 | BU5: 10000000 | BV5: 0 | BW5: 0 | BX5: 0 | BY5: 11000000 | BZ5: 2 | CA5: 8800000 | CB5: 800000 | CC5: 100000 | CD5: 150000 | CE5: 0 | CF5: 1050000 | CG5: 20850000 | CH5: 0 | CI5: 0 | CK5: 0 | CL5: 0 | CM5: 100000 | CN5: 0 | CP5: 310000 | CQ5: 0 | CR5: 410000 | CS5: 8540000 | CU5: 8540000 | CV5: 1700000 | CW5: 0 | CX5: 300000 | CY5: 0 | DA5: 2000000 | DB5: 3050000 | DC5: 200000 | DD5: 12200000 | DF5: Việt PhúSouthFinance | DG5: 833333.33 | DH5: HO | DI5: =IFERROR(VLOOKUP($B5,[1]Timesheet!$D:$BK,51,0),0) -> 18 | DJ5: =IFERROR(VLOOKUP($B5,[1]Timesheet!$D:$BK,52,0),0) -> 0 | DK5: =IFERROR(VLOOKUP($B5,[1]Timesheet!$D:$BK,55,0),0) -> 0 | DL5: x | DM5: =IFERROR(VLOOKUP($B5,[1]Timesheet!$D:$BK,57,0),0) -> 0 | DN5: =IF(AND(DL5="x",CB5>0),MIN(ROUND(W5*1%,0),149000),0) -> 100000 | DP5: =IF(E5="Sales",IF(F5="Logistics",F5,IF(F5="Marketing",F5,DH5)),"") | DQ5: 43595 | DR5: 43777 | DS5: =IFERROR(VLOOKUP(E5&H5,[1]Group!$D$3:$G$40,4,0),"") | DT5: =J5&I5&DS5 -> Việt PhúSouth
A6: 3 | B6: 5162 | C6: VP005162 | D6: Lưu Nguyễn Phương Uyên | E6: Finance | F6: Accounting & Tax | G6: Senior Associate | H6: General Accountant | I6: South | J6: Việt Phú | K6: Full-time | L6: Permanent | M6: 43668 | Q6: LC | R6: LTTP | S6: L | U6: 10000000 | W6: 10000000 | X6: 0 | Y6: 0 | AA6: 0 | AC6: 0 | AD6: 0 | AE6: TB, CN | AF6: 21 | AG6: 21 | AH6: 0 | AI6: 0 | AJ6: 0 | AK6: 21 | AL6: 0 | AM6: 0 | AN6: 0 | AO6: 0 | AP6: 0 | AQ6: 0 | AR6: 10000000 | AS6: 0 | AT6: 0 | AU6: 10000000 | AV6: 0 | AW6: 0 | AX6: 0 | AY6: 0 | AZ6: 0 | BA6: 0 | BE6: 0 | BF6: 0 | BG6: 0 | BH6: 0 | BI6: 0 | BJ6: 0 | BL6: 0 | BO6: 0 | BT6: 0 | BU6: 10000000 | BV6: 0 | BW6: 0 | BX6: 0 | BY6: 11000000 | BZ6: 0 | CA6: 0 | CB6: 800000 | CC6: 100000 | CD6: 150000 | CE6: 0 | CF6: 1050000 | CG6: 12050000 | CH6: 0 | CI6: 0 | CK6: 0 | CL6: 0 | CM6: 0 | CN6: 0 | CP6: 5500 | CQ6: 0 | CR6: 5500 | CS6: 8944500 | CU6: 8944500 | CV6: 1700000 | CW6: 0 | CX6: 300000 | CY6: 0 | DA6: 2000000 | DB6: 3050000 | DC6: 200000 | DD6: 12200000 | DF6: Việt PhúSouthFinance | DG6: 833333.33 | DH6: HO | DI6: =IFERROR(VLOOKUP($B6,[1]Timesheet!$D:$BK,51,0),0) -> 18 | DJ6: =IFERROR(VLOOKUP($B6,[1]Timesheet!$D:$BK,52,0),0) -> 0 | DK6: =IFERROR(VLOOKUP($B6,[1]Timesheet!$D:$BK,55,0),0) -> 0 | DL6: 0 | DM6: =IFERROR(VLOOKUP($B6,[1]Timesheet!$D:$BK,57,0),0) -> 0 | DN6: =IF(AND(DL6="x",CB6>0),MIN(ROUND(W6*1%,0),149000),0) -> 0 | DP6: =IF(E6="Sales",IF(F6="Logistics",F6,IF(F6="Marketing",F6,DH6)),"") | DQ6: 0 | DR6: 0 | DS6: =IFERROR(VLOOKUP(E6&H6,[1]Group!$D$3:$G$40,4,0),"") | DT6: =J6&I6&DS6 -> Việt PhúSouth
A7: 4 | B7: 5368 | C7: VP005368 | D7: Phan Thị Hải | E7: Finance | F7: Accounting & Tax | G7: Senior Associate | H7: General Accountant | I7: South | J7: Việt Phú | K7: Full-time | L7: Permanent | M7: 43739 | Q7: LC | R7: LTTP | S7: L | U7: 10000000 | W7: 10000000 | X7: 0 | Y7: 0 | AA7: 0 | AC7: 0 | AD7: 0 | AE7: TB, CN | AF7: 21 | AG7: 21 | AH7: 0 | AI7: 0 | AJ7: 0 | AK7: 21 | AL7: 0 | AM7: 0 | AN7: 0 | AO7: 0 | AP7: 0 | AQ7: 0 | AR7: 10000000 | AS7: 0 | AT7: 0 | AU7: 10000000 | AV7: 0 | AW7: 0 | AX7: 0 | AY7: 0 | AZ7: 0 | BA7: 0 | BE7: 0 | BF7: 0 | BG7: 0 | BH7: 0 | BI7: 0 | BJ7: 0 | BL7: 0 | BO7: 0 | BT7: 0 | BU7: 10000000 | BV7: 0 | BW7: 0 | BX7: 0 | BY7: 11000000 | BZ7: 1 | CA7: 4400000 | CB7: 800000 | CC7: 100000 | CD7: 150000 | CE7: 0 | CF7: 1050000 | CG7: 16450000 | CH7: 0 | CI7: 0 | CK7: 0 | CL7: 0 | CM7: 100000 | CN7: 0 | CP7: 0 | CQ7: 0 | CR7: 100000 | CS7: 8850000 | CU7: 8850000 | CV7: 1700000 | CW7: 0 | CX7: 300000 | CY7: 0 | DA7: 2000000 | DB7: 3050000 | DC7: 200000 | DD7: 12200000 | DF7: Việt PhúSouthFinance | DG7: 833333.33 | DH7: HO | DI7: =IFERROR(VLOOKUP($B7,[1]Timesheet!$D:$BK,51,0),0) -> 18 | DJ7: =IFERROR(VLOOKUP($B7,[1]Timesheet!$D:$BK,52,0),0) -> 0 | DK7: =IFERROR(VLOOKUP($B7,[1]Timesheet!$D:$BK,55,0),0) -> 0 | DL7: x | DM7: =IFERROR(VLOOKUP($B7,[1]Timesheet!$D:$BK,57,0),0) -> 0 | DN7: =IF(AND(DL7="x",CB7>0),MIN(ROUND(W7*1%,0),149000),0) -> 100000 | DP7: =IF(E7="Sales",IF(F7="Logistics",F7,IF(F7="Marketing",F7,DH7)),"") | DQ7: 0 | DR7: 0 | DS7: =IFERROR(VLOOKUP(E7&H7,[1]Group!$D$3:$G$40,4,0),"") | DT7: =J7&I7&DS7 -> Việt PhúSouth
A8: 5 | B8: 1464 | C8: VP001464 | D8: Lê Thị Cẩm Nhung | E8: Finance | F8: Funding | G8: Senior Associate | H8: Funding - Banking Relationship | I8: South | J8: Việt Phú | K8: Full-time | L8: Permanent | M8: 41680 | Q8: LC | R8: LTTP | S8: L | U8: 10000000 | W8: 10000000 | X8: 0 | Y8: 0 | AA8: 0 | AC8: 0 | AD8: 0 | AE8: TB, CN | AF8: 21 | AG8: 21 | AH8: 0 | AI8: 0 | AJ8: 0 | AK8: 21 | AL8: 0 | AM8: 0 | AN8: 0 | AO8: 0 | AP8: 0 | AQ8: 0 | AR8: 10000000 | AS8: 0 | AT8: 0 | AU8: 10000000 | AV8: 0 | AW8: 0 | AX8: 0 | AY8: 0 | AZ8: 0 | BA8: 0 | BE8: 0 | BF8: 0 | BG8: 0 | BH8: 0 | BI8: 0 | BJ8: 0 | BL8: 0 | BO8: 0 | BT8: 0 | BU8: 10000000 | BV8: 0 | BW8: 0 | BX8: 0 | BY8: 11000000 | BZ8: 1 | CA8: 4400000 | CB8: 800000 | CC8: 100000 | CD8: 150000 | CE8: 0 | CF8: 1050000 | CG8: 16450000 | CH8: 0 | CI8: 0 | CK8: 0 | CL8: 0 | CM8: 100000 | CN8: 0 | CP8: 174000 | CQ8: 0 | CR8: 274000 | CS8: 8676000 | CU8: 8676000 | CV8: 1700000 | CW8: 0 | CX8: 300000 | CY8: 0 | DA8: 2000000 | DB8: 3050000 | DC8: 200000 | DD8: 12200000 | DF8: Việt PhúSouthFinance | DG8: 833333.33 | DH8: HO | DI8: =IFERROR(VLOOKUP($B8,[1]Timesheet!$D:$BK,51,0),0) -> 18 | DJ8: =IFERROR(VLOOKUP($B8,[1]Timesheet!$D:$BK,52,0),0) -> 0 | DK8: =IFERROR(VLOOKUP($B8,[1]Timesheet!$D:$BK,55,0),0) -> 0 | DL8: x | DM8: =IFERROR(VLOOKUP($B8,[1]Timesheet!$D:$BK,57,0),0) -> 0 | DN8: =IF(AND(DL8="x",CB8>0),MIN(ROUND(W8*1%,0),149000),0) -> 100000 | DP8: =IF(E8="Sales",IF(F8="Logistics",F8,IF(F8="Marketing",F8,DH8)),"") | DQ8: 0 | DR8: 0 | DS8: =IFERROR(VLOOKUP(E8&H8,[1]Group!$D$3:$G$40,4,0),"") | DT8: =J8&I8&DS8 -> Việt PhúSouth
A9: 6 | B9: 4767 | C9: VP004767 | D9: Hoàng Thị Minh Châu | E9: Finance | F9: Planning & Analysis | G9: HOD | H9: Head of Finance | I9: South | J9: Việt Phú | K9: Full-time | L9: Maternity | M9: 43314 | N9: 15/09/2021 - 14/03/2022 | Q9: LC | R9: LTTP | S9: L | U9: 80000000 | W9: 80000000 | X9: 0 | Y9: 0 | AA9: 0 | AC9: 0 | AD9: 0 | AE9: TB, CN | AF9: 21 | AG9: 0 | AH9: 0 | AI9: 0 | AJ9: 0 | AK9: 0 | AL9: 0 | AM9: 0 | AN9: 0 | AO9: 0 | AP9: 0 | AQ9: 0 | AR9: 0 | AS9: 0 | AT9: 0 | AU9: 0 | AV9: 0 | AW9: 0 | AX9: 0 | AY9: 0 | AZ9: 0 | BA9: 0 | BE9: 0 | BF9: 0 | BG9: 0 | BH9: 0 | BI9: 0 | BJ9: 0 | BL9: 0 | BO9: 0 | BT9: 0 | BU9: 0 | BV9: 0 | BW9: 0 | BX9: 0 | BY9: 11000000 | BZ9: 0 | CA9: 0 | CB9: 0 | CC9: 0 | CD9: 0 | CE9: 0 | CF9: 0 | CG9: 11000000 | CH9: 0 | CI9: 0 | CK9: 0 | CL9: 0 | CM9: 0 | CN9: 0 | CP9: 0 | CQ9: 0 | CR9: 0 | CS9: 0 | CU9: 0 | CV9: 0 | CW9: 0 | CX9: 0 | CY9: 0 | DA9: 0 | DB9: 0 | DC9: 0 | DD9: 0 | DF9: Việt PhúSouthFinance | DG9: 6666666.7 | DH9: HO | DI9: =IFERROR(VLOOKUP($B9,[1]Timesheet!$D:$BK,51,0),0) -> 0 | DJ9: =IFERROR(VLOOKUP($B9,[1]Timesheet!$D:$BK,52,0),0) -> 0 | DK9: =IFERROR(VLOOKUP($B9,[1]Timesheet!$D:$BK,55,0),0) -> 0 | DL9: 0 | DM9: =IFERROR(VLOOKUP($B9,[1]Timesheet!$D:$BK,57,0),0) -> 0 | DN9: =IF(AND(DL9="x",CB9>0),MIN(ROUND(W9*1%,0),149000),0) -> 0 | DP9: =IF(E9="Sales",IF(F9="Logistics",F9,IF(F9="Marketing",F9,DH9)),"") | DQ9: 44454 | DR9: 44634 | DS9: =IFERROR(VLOOKUP(E9&H9,[1]Group!$D$3:$G$40,4,0),"") | DT9: =J9&I9&DS9 -> Việt PhúSouth
A10: 7 | B10: 6176 | C10: VP006176 | D10: Nguyễn Hải Hà | E10: Finance | F10: Planning & Analysis | G10: Associate | H10: Finance Analyst | I10: South | J10: Việt Phú | K10: Full-time | L10: Permanent | M10: 44382 | Q10: LC | R10: LTTP | S10: L | U10: 5000000 | W10: 5000000 | X10: 0 | Y10: 0 | AA10: 0 | AC10: 0 | AD10: 0 | AE10: TB, CN | AF10: 21 | AG10: 21 | AH10: 0 | AI10: 0 | AJ10: 0 | AK10: 21 | AL10: 0 | AM10: 0 | AN10: 0 | AO10: 0 | AP10: 0 | AQ10: 0 | AR10: 5000000 | AS10: 0 | AT10: 0 | AU10: 5000000 | AV10: 0 | AW10: 0 | AX10: 0 | AY10: 0 | AZ10: 0 | BA10: 0 | BE10: 0 | BF10: 0 | BG10: 0 | BH10: 0 | BI10: 0 | BJ10: 0 | BL10: 0 | BO10: 0 | BT10: 0 | BU10: 5000000 | BV10: 0 | BW10: 0 | BX10: 0 | BY10: 11000000 | BZ10: 0 | CA10: 0 | CB10: 400000 | CC10: 50000 | CD10: 75000 | CE10: 0 | CF10: 525000 | CG10: 11525000 | CH10: 0 | CI10: 0 | CK10: 0 | CL10: 0 | CM10: 0 | CN10: 0 | CP10: 0 | CQ10: 0 | CR10: 0 | CS10: 4475000 | CU10: 4475000 | CV10: 850000 | CW10: 0 | CX10: 150000 | CY10: 0 | DA10: 1000000 | DB10: 1525000 | DC10: 100000 | DD10: 6100000 | DF10: Việt PhúSouthFinance | DG10: 416666.67 | DH10: HO | DI10: =IFERROR(VLOOKUP($B10,[1]Timesheet!$D:$BK,51,0),0) -> 18 | DJ10: =IFERROR(VLOOKUP($B10,[1]Timesheet!$D:$BK,52,0),0) -> 0 | DK10: =IFERROR(VLOOKUP($B10,[1]Timesheet!$D:$BK,55,0),0) -> 0 | DL10: 0 | DM10: =IFERROR(VLOOKUP($B10,[1]Timesheet!$D:$BK,57,0),0) -> 0 | DN10: =IF(AND(DL10="x",CB10>0),MIN(ROUND(W10*1%,0),149000),0) -> 0 | DP10: =IF(E10="Sales",IF(F10="Logistics",F10,IF(F10="Marketing",F10,DH10)),"") | DQ10: 0 | DR10: 0 | DS10: =IFERROR(VLOOKUP(E10&H10,[1]Group!$D$3:$G$40,4,0),"") | DT10: =J10&I10&DS10 -> Việt PhúSouth
A11: 8 | B11: 6197 | C11: VP006197 | D11: Trần Minh Tâm | E11: Finance | F11: Bank Partnership | G11: Manager | H11: Bank Partnership Manager | I11: South | J11: Việt Phú | K11: Full-time | L11: Permanent | M11: 44445 | Q11: LC | R11: LTTP | S11: L | U11: 40000000 | W11: 40000000 | X11: 0 | Y11: 0 | AA11: 0 | AC11: 0 | AD11: 0 | AE11: TB, CN | AF11: 21 | AG11: 19 | AH11: 2 | AI11: 0 | AJ11: 0 | AK11: 21 | AL11: 0 | AM11: 0 | AN11: 0 | AO11: 0 | AP11: 0 | AQ11: 0 | AR11: 40000000 | AS11: 0 | AT11: 0 | AU11: 40000000 | AV11: 0 | AW11: 0 | AX11: 0 | AY11: 0 | AZ11: 0 | BA11: 0 | BE11: 0 | BF11: 0 | BG11: 0 | BH11: 0 | BI11: 0 | BJ11: 0 | BL11: 0 | BO11: 0 | BT11: 0 | BU11: 40000000 | BV11: 0 | BW11: 0 | BX11: 0 | BY11: 11000000 | BZ11: 0 | CA11: 0 | CB11: 2384000 | CC11: 400000 | CD11: 447000 | CE11: 0 | CF11: 3231000 | CG11: 14231000 | CH11: 25769000 | CI11: 3503800 | CK11: 3503800 | CL11: 0 | CM11: 149000 | CN11: 0 | CP11: 0 | CQ11: 0 | CR11: 149000 | CS11: 33116200 | CU11: 33116200 | CV11: 5066000 | CW11: 0 | CX11: 894000 | CY11: 0 | DA11: 5960000 | DB11: 9191000 | DC11: 596000 | DD11: 46556000 | DF11: Việt PhúSouthFinance | DG11: 3333333.3 | DH11: HO | DI11: =IFERROR(VLOOKUP($B11,[1]Timesheet!$D:$BK,51,0),0) -> 18 | DJ11: =IFERROR(VLOOKUP($B11,[1]Timesheet!$D:$BK,52,0),0) -> 0 | DK11: =IFERROR(VLOOKUP($B11,[1]Timesheet!$D:$BK,55,0),0) -> 0 | DL11: x | DM11: =IFERROR(VLOOKUP($B11,[1]Timesheet!$D:$BK,57,0),0) -> 0 | DN11: =IF(AND(DL11="x",CB11>0),MIN(ROUND(W11*1%,0),149000),0) -> 149000 | DP11: =IF(E11="Sales",IF(F11="Logistics",F11,IF(F11="Marketing",F11,DH11)),"") | DQ11: 0 | DR11: 0 | DS11: =IFERROR(VLOOKUP(E11&H11,[1]Group!$D$3:$G$40,4,0),"") | DT11: =J11&I11&DS11 -> Việt PhúSouth
A12: 9 | B12: 5456 | C12: VP005456 | D12: Nguyễn Thị Hồng Đào | E12: Finance | F12: Accounting & Tax | G12: Associate | H12: Accounting Officer | I12: South | J12: Việt Phú | K12: Full-time | L12: Permanent | M12: 43759 | Q12: LC | R12: LTTP | S12: L | U12: 5000000 | W12: 5000000 | X12: 0 | Y12: 0 | AA12: 0 | AC12: 0 | AD12: 0 | AE12: TB, CN | AF12: 21 | AG12: 21 | AH12: 0 | AI12: 0 | AJ12: 0 | AK12: 21 | AL12: 0 | AM12: 0 | AN12: 0 | AO12: 0 | AP12: 0 | AQ12: 0 | AR12: 5000000 | AS12: 0 | AT12: 0 | AU12: 5000000 | AV12: 0 | AW12: 0 | AX12: 0 | AY12: 0 | AZ12: 0 | BA12: 0 | BE12: 0 | BF12: 0 | BG12: 0 | BH12: 0 | BI12: 0 | BJ12: 0 | BL12: 0 | BO12: 0 | BT12: 0 | BU12: 5000000 | BV12: 0 | BW12: 0 | BX12: 0 | BY12: 11000000 | BZ12: 0 | CA12: 0 | CB12: 400000 | CC12: 50000 | CD12: 75000 | CE12: 0 | CF12: 525000 | CG12: 11525000 | CH12: 0 | CI12: 0 | CK12: 0 | CL12: 0 | CM12: 0 | CN12: 0 | CP12: 0 | CQ12: 0 | CR12: 0 | CS12: 4475000 | CU12: 4475000 | CV12: 850000 | CW12: 0 | CX12: 150000 | CY12: 0 | DA12: 1000000 | DB12: 1525000 | DC12: 100000 | DD12: 6100000 | DF12: Việt PhúSouthFinance | DG12: 416666.67 | DH12: HO | DI12: =IFERROR(VLOOKUP($B12,[1]Timesheet!$D:$BK,51,0),0) -> 18 | DJ12: =IFERROR(VLOOKUP($B12,[1]Timesheet!$D:$BK,52,0),0) -> 0 | DK12: =IFERROR(VLOOKUP($B12,[1]Timesheet!$D:$BK,55,0),0) -> 0 | DL12: 0 | DM12: =IFERROR(VLOOKUP($B12,[1]Timesheet!$D:$BK,57,0),0) -> 0 | DN12: =IF(AND(DL12="x",CB12>0),MIN(ROUND(W12*1%,0),149000),0) -> 0 | DP12: =IF(E12="Sales",IF(F12="Logistics",F12,IF(F12="Marketing",F12,DH12)),"") | DQ12: 0 | DR12: 0 | DS12: =IFERROR(VLOOKUP(E12&H12,[1]Group!$D$3:$G$40,4,0),"") | DT12: =J12&I12&DS12 -> Việt PhúSouth
A13: 10 | B13: 5679 | C13: VP005679 | D13: Quách Thị Phượng | E13: Finance | F13: Facilities & Workplace support | G13: Manager | H13: Manager, Work Place Support | I13: South | J13: Việt Phú | K13: Full-time | L13: Permanent | M13: 43964 | Q13: LC | R13: LTTP | S13: L | U13: 40000000 | W13: 40000000 | X13: 0 | Y13: 0 | AA13: 0 | AC13: 0 | AD13: 0 | AE13: TB, CN | AF13: 21 | AG13: 15 | AH13: 6 | AI13: 0 | AJ13: 0 | AK13: 21 | AL13: 0 | AM13: 0 | AN13: 0 | AO13: 0 | AP13: 0 | AQ13: 0 | AR13: 40000000 | AS13: 0 | AT13: 0 | AU13: 40000000 | AV13: 0 | AW13: 0 | AX13: 0 | AY13: 0 | AZ13: 0 | BA13: 0 | BE13: 0 | BF13: 0 | BG13: 0 | BH13: 0 | BI13: 0 | BJ13: 0 | BL13: 0 | BO13: 0 | BT13: 0 | BU13: 40000000 | BV13: 0 | BW13: 0 | BX13: 0 | BY13: 11000000 | BZ13: 3 | CA13: 13200000 | CB13: 2384000 | CC13: 400000 | CD13: 447000 | CE13: 0 | CF13: 3231000 | CG13: 27431000 | CH13: 12569000 | CI13: 1135350 | CK13: 1135350 | CL13: 0 | CM13: 149000 | CN13: 0 | CP13: 0 | CQ13: 0 | CR13: 149000 | CS13: 35484650 | CU13: 35484650 | CV13: 5066000 | CW13: 0 | CX13: 894000 | CY13: 0 | DA13: 5960000 | DB13: 9191000 | DC13: 596000 | DD13: 46556000 | DF13: Việt PhúSouthFinance | DG13: 3333333.3 | DH13: HO | DI13: =IFERROR(VLOOKUP($B13,[1]Timesheet!$D:$BK,51,0),0) -> 18 | DJ13: =IFERROR(VLOOKUP($B13,[1]Timesheet!$D:$BK,52,0),0) -> 0 | DK13: =IFERROR(VLOOKUP($B13,[1]Timesheet!$D:$BK,55,0),0) -> 0 | DL13: x | DM13: =IFERROR(VLOOKUP($B13,[1]Timesheet!$D:$BK,57,0),0) -> 0 | DN13: =IF(AND(DL13="x",CB13>0),MIN(ROUND(W13*1%,0),149000),0) -> 149000 | DP13: =IF(E13="Sales",IF(F13="Logistics",F13,IF(F13="Marketing",F13,DH13)),"") | DQ13: 0 | DR13: 0 | DS13: =IFERROR(VLOOKUP(E13&H13,[1]Group!$D$3:$G$40,4,0),"") | DT13: =J13&I13&DS13 -> Việt PhúSouth
A14: 11 | B14: 4962 | C14: VP004962 | D14: Lê Thị Bạch Kim | E14: Finance | F14: Facilities & Workplace support | G14: Associate | H14: Personal Assistant cum Admin | I14: South | J14: Việt Phú | K14: Full-time | L14: Permanent | M14: 43530 | Q14: LC | R14: LTTP | S14: L | U14: 5000000 | W14: 5000000 | X14: 0 | Y14: 0 | AA14: 0 | AC14: 0 | AD14: 0 | AE14: TB, CN | AF14: 21 | AG14: 16 | AH14: 5 | AI14: 0 | AJ14: 0 | AK14: 21 | AL14: 0 | AM14: 0 | AN14: 0 | AO14: 0 | AP14: 0 | AQ14: 0 | AR14: 5000000 | AS14: 0 | AT14: 0 | AU14: 5000000 | AV14: 0 | AW14: 0 | AX14: 0 | AY14: 0 | AZ14: 0 | BA14: 0 | BE14: 0 | BF14: 0 | BG14: 0 | BH14: 0 | BI14: 0 | BJ14: 0 | BL14: 0 | BO14: 0 | BT14: 0 | BU14: 5000000 | BV14: 0 | BW14: 0 | BX14: 0 | BY14: 11000000 | BZ14: 0 | CA14: 0 | CB14: 400000 | CC14: 50000 | CD14: 75000 | CE14: 0 | CF14: 525000 | CG14: 11525000 | CH14: 0 | CI14: 0 | CK14: 0 | CL14: 0 | CM14: 50000 | CN14: 0 | CP14: 137000 | CQ14: 0 | CR14: 187000 | CS14: 4288000 | CU14: 4288000 | CV14: 850000 | CW14: 0 | CX14: 150000 | CY14: 0 | DA14: 1000000 | DB14: 1525000 | DC14: 100000 | DD14: 6100000 | DF14: Việt PhúSouthFinance | DG14: 416666.67 | DH14: HO | DI14: =IFERROR(VLOOKUP($B14,[1]Timesheet!$D:$BK,51,0),0) -> 18 | DJ14: =IFERROR(VLOOKUP($B14,[1]Timesheet!$D:$BK,52,0),0) -> 0 | DK14: =IFERROR(VLOOKUP($B14,[1]Timesheet!$D:$BK,55,0),0) -> 0 | DL14: x | DM14: =IFERROR(VLOOKUP($B14,[1]Timesheet!$D:$BK,57,0),0) -> 0 | DN14: =IF(AND(DL14="x",CB14>0),MIN(ROUND(W14*1%,0),149000),0) -> 50000 | DP14: =IF(E14="Sales",IF(F14="Logistics",F14,IF(F14="Marketing",F14,DH14)),"") | DQ14: 44161 | DR14: 44341 | DS14: =IFERROR(VLOOKUP(E14&H14,[1]Group!$D$3:$G$40,4,0),"") | DT14: =J14&I14&DS14 -> Việt PhúSouth
A15: 12 | B15: 5688 | C15: VP005688 | D15: Nguyễn Thụy Thanh Xuân | E15: Finance | F15: Facilities & Workplace support | G15: Associate | H15: Administration Officer | I15: South | J15: Việt Phú | K15: Full-time | L15: Permanent | M15: 43977 | Q15: LC | R15: LTTP | S15: L | U15: 5000000 | W15: 5000000 | X15: 0 | Y15: 0 | AA15: 0 | AC15: 0 | AD15: 0 | AE15: TB, CN | AF15: 21 | AG15: 16 | AH15: 5 | AI15: 0 | AJ15: 0 | AK15: 21 | AL15: 0 | AM15: 0 | AN15: 0 | AO15: 0 | AP15: 0 | AQ15: 0 | AR15: 5000000 | AS15: 0 | AT15: 0 | AU15: 5000000 | AV15: 0 | AW15: 0 | AX15: 0 | AY15: 0 | AZ15: 0 | BA15: 0 | BE15: 0 | BF15: 0 | BG15: 0 | BH15: 0 | BI15: 0 | BJ15: 0 | BL15: 0 | BO15: 0 | BT15: 0 | BU15: 5000000 | BV15: 0 | BW15: 0 | BX15: 0 | BY15: 11000000 | BZ15: 0 | CA15: 0 | CB15: 400000 | CC15: 50000 | CD15: 75000 | CE15: 0 | CF15: 525000 | CG15: 11525000 | CH15: 0 | CI15: 0 | CK15: 0 | CL15: 0 | CM15: 50000 | CN15: 0 | CP15: 0 | CQ15: 0 | CR15: 50000 | CS15: 4425000 | CU15: 4425000 | CV15: 850000 | CW15: 0 | CX15: 150000 | CY15: 0 | DA15: 1000000 | DB15: 1525000 | DC15: 100000 | DD15: 6100000 | DF15: Việt PhúSouthFinance | DG15: 416666.67 | DH15: HO | DI15: =IFERROR(VLOOKUP($B15,[1]Timesheet!$D:$BK,51,0),0) -> 18 | DJ15: =IFERROR(VLOOKUP($B15,[1]Timesheet!$D:$BK,52,0),0) -> 0 | DK15: =IFERROR(VLOOKUP($B15,[1]Timesheet!$D:$BK,55,0),0) -> 0 | DL15: x | DM15: =IFERROR(VLOOKUP($B15,[1]Timesheet!$D:$BK,57,0),0) -> 0 | DN15: =IF(AND(DL15="x",CB15>0),MIN(ROUND(W15*1%,0),149000),0) -> 50000 | DP15: =IF(E15="Sales",IF(F15="Logistics",F15,IF(F15="Marketing",F15,DH15)),"") | DQ15: 0 | DR15: 0 | DS15: =IFERROR(VLOOKUP(E15&H15,[1]Group!$D$3:$G$40,4,0),"") | DT15: =J15&I15&DS15 -> Việt PhúSouth
A16: 13 | B16: 6037 | C16: VP006037 | D16: Châu Hùng Minh | E16: Finance | F16: Facilities & Workplace support | G16: Associate | H16: Work Place Technician | I16: South | J16: Việt Phú | K16: Full-time | L16: Permanent | M16: 44167 | Q16: LC | R16: LTTP | S16: L | U16: 5000000 | W16: 5000000 | X16: 0 | Y16: 0 | AA16: 0 | AC16: 0 | AD16: 0 | AE16: TB, CN | AF16: 21 | AG16: 16 | AH16: 5 | AI16: 0 | AJ16: 0 | AK16: 21 | AL16: 0 | AM16: 0 | AN16: 0 | AO16: 0 | AP16: 0 | AQ16: 0 | AR16: 5000000 | AS16: 0 | AT16: 0 | AU16: 5000000 | AV16: 0 | AW16: 0 | AX16: 0 | AY16: 0 | AZ16: 0 | BA16: 0 | BE16: 0 | BF16: 0 | BG16: 0 | BH16: 0 | BI16: 0 | BJ16: 0 | BL16: 0 | BO16: 0 | BT16: 0 | BU16: 5000000 | BV16: 0 | BW16: 0 | BX16: 0 | BY16: 11000000 | BZ16: 0 | CA16: 0 | CB16: 400000 | CC16: 50000 | CD16: 75000 | CE16: 0 | CF16: 525000 | CG16: 11525000 | CH16: 0 | CI16: 0 | CK16: 0 | CL16: 0 | CM16: 50000 | CN16: 0 | CP16: 0 | CQ16: 0 | CR16: 50000 | CS16: 4425000 | CU16: 4425000 | CV16: 850000 | CW16: 0 | CX16: 150000 | CY16: 0 | DA16: 1000000 | DB16: 1525000 | DC16: 100000 | DD16: 6100000 | DF16: Việt PhúSouthFinance | DG16: 416666.67 | DH16: HO | DI16: =IFERROR(VLOOKUP($B16,[1]Timesheet!$D:$BK,51,0),0) -> 18 | DJ16: =IFERROR(VLOOKUP($B16,[1]Timesheet!$D:$BK,52,0),0) -> 0 | DK16: =IFERROR(VLOOKUP($B16,[1]Timesheet!$D:$BK,55,0),0) -> 0 | DL16: x | DM16: =IFERROR(VLOOKUP($B16,[1]Timesheet!$D:$BK,57,0),0) -> 0 | DN16: =IF(AND(DL16="x",CB16>0),MIN(ROUND(W16*1%,0),149000),0) -> 50000 | DP16: =IF(E16="Sales",IF(F16="Logistics",F16,IF(F16="Marketing",F16,DH16)),"") | DQ16: 0 | DR16: 0 | DS16: =IFERROR(VLOOKUP(E16&H16,[1]Group!$D$3:$G$40,4,0),"") | DT16: =J16&I16&DS16 -> Việt PhúSouth
A17: 14 | B17: 5701 | C17: VP005701 | D17: Nguyễn Thị Xây | E17: Finance | F17: Facilities & Workplace support | G17: Associate | H17: Cleaner (HN Office) | I17: North | J17: Việt Phú | K17: Contractor | L17: Contractor | M17: 43977 | Q17: SC | R17: 0.1 | S17: L | U17: 5000000 | W17: 5000000 | X17: 0 | Y17: 0 | AA17: 0 | AC17: 0 | AD17: 0 | AE17: CN | AF17: 26 | AG17: 26 | AH17: 0 | AI17: 0 | AJ17: 0 | AK17: 26 | AL17: 0 | AM17: 0 | AN17: 0 | AO17: 0 | AP17: 0 | AQ17: 0 | AR17: 5000000 | AS17: 0 | AT17: 0 | AU17: 5000000 | AV17: 0 | AW17: 0 | AX17: 0 | AY17: 0 | AZ17: 0 | BA17: 0 | BE17: 0 | BF17: 0 | BG17: 0 | BH17: 0 | BI17: 0 | BJ17: 0 | BL17: 0 | BO17: 0 | BT17: 0 | BU17: 5000000 | BV17: 0 | BW17: 0 | BX17: 0 | BY17: 0 | BZ17: 0 | CA17: 0 | CB17: 0 | CC17: 0 | CD17: 0 | CE17: 0 | CF17: 0 | CG17: 0 | CH17: 5000000 | CI17: 500000 | CK17: 500000 | CL17: 0 | CM17: 0 | CN17: 0 | CP17: 0 | CQ17: 0 | CR17: 0 | CS17: 4500000 | CU17: 4500000 | CV17: 0 | CW17: 0 | CX17: 0 | CY17: 0 | DA17: 0 | DB17: 0 | DC17: 0 | DD17: 5000000 | DF17: Việt PhúNorthFinance | DG17: 416666.67 | DH17: HNI | DI17: =IFERROR(VLOOKUP($B17,[1]Timesheet!$D:$BK,51,0),0) -> 22 | DJ17: =IFERROR(VLOOKUP($B17,[1]Timesheet!$D:$BK,52,0),0) -> 0 | DK17: =IFERROR(VLOOKUP($B17,[1]Timesheet!$D:$BK,55,0),0) -> 0 | DL17: 0 | DM17: =IFERROR(VLOOKUP($B17,[1]Timesheet!$D:$BK,57,0),0) -> 0 | DN17: =IF(AND(DL17="x",CB17>0),MIN(ROUND(W17*1%,0),149000),0) -> 0 | DP17: =IF(E17="Sales",IF(F17="Logistics",F17,IF(F17="Marketing",F17,DH17)),"") | DQ17: 0 | DR17: 0 | DS17: =IFERROR(VLOOKUP(E17&H17,[1]Group!$D$3:$G$40,4,0),"") | DT17: =J17&I17&DS17 -> Việt PhúNorth
A18: 15 | B18: 6109 | C18: VP006109 | D18: Lê Thị Kiều Diễm | E18: Finance | F18: Facilities & Workplace support | G18: Associate | H18: Work Place Procurement Officer | I18: South | J18: Việt Phú | K18: Full-time | L18: Permanent | M18: 44300 | Q18: LC | R18: LTTP | S18: L | U18: 5000000 | W18: 5000000 | X18: 0 | Y18: 0 | AA18: 0 | AC18: 0 | AD18: 0 | AE18: TB, CN | AF18: 21 | AG18: 17.5 | AH18: 3.5 | AI18: 0 | AJ18: 0 | AK18: 21 | AL18: 0 | AM18: 0 | AN18: 0 | AO18: 0 | AP18: 0 | AQ18: 0 | AR18: 5000000 | AS18: 0 | AT18: 0 | AU18: 5000000 | AV18: 0 | AW18: 0 | AX18: 0 | AY18: 0 | AZ18: 0 | BA18: 0 | BE18: 0 | BF18: 0 | BG18: 0 | BH18: 0 | BI18: 0 | BJ18: 0 | BL18: 0 | BO18: 0 | BT18: 0 | BU18: 5000000 | BV18: 0 | BW18: 0 | BX18: 0 | BY18: 11000000 | BZ18: 0 | CA18: 0 | CB18: 400000 | CC18: 50000 | CD18: 75000 | CE18: 0 | CF18: 525000 | CG18: 11525000 | CH18: 0 | CI18: 0 | CK18: 0 | CL18: 0 | CM18: 50000 | CN18: 0 | CP18: 0 | CQ18: 0 | CR18: 50000 | CS18: 4425000 | CU18: 4425000 | CV18: 850000 | CW18: 0 | CX18: 150000 | CY18: 0 | DA18: 1000000 | DB18: 1525000 | DC18: 100000 | DD18: 6100000 | DF18: Việt PhúSouthFinance | DG18: 416666.67 | DH18: HO | DI18: =IFERROR(VLOOKUP($B18,[1]Timesheet!$D:$BK,51,0),0) -> 18 | DJ18: =IFERROR(VLOOKUP($B18,[1]Timesheet!$D:$BK,52,0),0) -> 0 | DK18: =IFERROR(VLOOKUP($B18,[1]Timesheet!$D:$BK,55,0),0) -> 0 | DL18: x | DM18: =IFERROR(VLOOKUP($B18,[1]Timesheet!$D:$BK,57,0),0) -> 0 | DN18: =IF(AND(DL18="x",CB18>0),MIN(ROUND(W18*1%,0),149000),0) -> 50000 | DP18: =IF(E18="Sales",IF(F18="Logistics",F18,IF(F18="Marketing",F18,DH18)),"") | DQ18: 0 | DR18: 0 | DS18: =IFERROR(VLOOKUP(E18&H18,[1]Group!$D$3:$G$40,4,0),"") | DT18: =J18&I18&DS18 -> Việt PhúSouth
A19: 16 | B19: 5693 | C19: MV005693 | D19: Lê Trọng Đoan | E19: Supply Chain Management | F19: Logistics | G19: HOD | H19: Head of Logistics and Supply Chain Management | I19: South | J19: Movi | K19: Full-time | L19: Permanent | M19: 43983 | Q19: LC | R19: LTTP | S19: L | U19: 80000000 | W19: 80000000 | X19: 0 | Y19: 0 | AA19: 200000 | AC19: 0 | AD19: 200000 | AE19: TB, CN | AF19: 21 | AG19: 18 | AH19: 3 | AI19: 0 | AJ19: 0 | AK19: 21 | AL19: 0 | AM19: 0 | AN19: 0 | AO19: 0 | AP19: 0 | AQ19: 0 | AR19: 80000000 | AS19: 0 | AT19: 0 | AU19: 80000000 | AV19: 0 | AW19: 0 | AX19: 0 | AY19: 200000 | AZ19: 0 | BA19: 0 | BE19: 0 | BF19: 200000 | BG19: 0 | BH19: 0 | BI19: 0 | BJ19: 0 | BL19: 0 | BO19: 0 | BT19: 0 | BU19: 80200000 | BV19: 0 | BW19: 200000 | BX19: 0 | BY19: 11000000 | BZ19: 1 | CA19: 4400000 | CB19: 2384000 | CC19: 800000 | CD19: 447000 | CE19: 0 | CF19: 3631000 | CG19: 19231000 | CH19: 60969000 | CI19: 12440700 | CK19: 12440700 | CL19: 0 | CM19: 149000 | CN19: 0 | CP19: 9238000 | CQ19: 0 | CR19: 9387000 | CS19: 54741300 | CU19: 54741300 | CV19: 5066000 | CW19: 0 | CX19: 894000 | CY19: 0 | DA19: 5960000 | DB19: 9591000 | DC19: 596000 | DD19: 86756000 | DF19: MoviSouthSupply Chain Management | DG19: 6666666.7 | DH19: HO | DI19: =IFERROR(VLOOKUP($B19,[1]Timesheet!$D:$BK,51,0),0) -> 18 | DJ19: =IFERROR(VLOOKUP($B19,[1]Timesheet!$D:$BK,52,0),0) -> 0 | DK19: =IFERROR(VLOOKUP($B19,[1]Timesheet!$D:$BK,55,0),0) -> 0 | DL19: x | DM19: =IFERROR(VLOOKUP($B19,[1]Timesheet!$D:$BK,57,0),0) -> 0 | DN19: =IF(AND(DL19="x",CB19>0),MIN(ROUND(W19*1%,0),149000),0) -> 149000 | DP19: =IF(E19="Sales",IF(F19="Logistics",F19,IF(F19="Marketing",F19,DH19)),"") | DQ19: 0 | DR19: 0 | DS19: =IFERROR(VLOOKUP(E19&H19,[1]Group!$D$3:$G$40,4,0),"") | DT19: =J19&I19&DS19 -> MoviSouth
A20: 17 | B20: 1909 | C20: MV001909 | D20: Trần Thị Bích | E20: Supply Chain Management | F20: Logistics | G20: Supervisor | H20: Logistics Supervisor | I20: Central | J20: Movi | K20: Full-time | L20: Permanent | M20: 42181 | Q20: LC | R20: LTTP | S20: L | U20: 20000000 | W20: 20000000 | X20: 0 | Y20: 0 | AA20: 100000 | AC20: 0 | AD20: 100000 | AE20: CN | AF20: 26 | AG20: 26 | AH20: 0 | AI20: 0 | AJ20: 0 | AK20: 26 | AL20: 0 | AM20: 0 | AN20: 0 | AO20: 0 | AP20: 0 | AQ20: 0 | AR20: 20000000 | AS20: 0 | AT20: 0 | AU20: 20000000 | AV20: 0 | AW20: 0 | AX20: 0 | AY20: 100000 | AZ20: 0 | BA20: 0 | BE20: 0 | BF20: 100000 | BG20: 0 | BH20: 0 | BI20: 0 | BJ20: 0 | BL20: 0 | BO20: 0 | BT20: 0 | BU20: 20100000 | BV20: 0 | BW20: 100000 | BX20: 0 | BY20: 11000000 | BZ20: 0 | CA20: 0 | CB20: 1600000 | CC20: 200000 | CD20: 300000 | CE20: 0 | CF20: 2100000 | CG20: 13200000 | CH20: 6900000 | CI20: 440000 | CK20: 440000 | CL20: 0 | CM20: 149000 | CN20: 0 | CP20: 833000 | CQ20: 0 | CR20: 982000 | CS20: 16578000 | CU20: 16578000 | CV20: 3400000 | CW20: 0 | CX20: 600000 | CY20: 0 | DA20: 4000000 | DB20: 6100000 | DC20: 400000 | DD20: 24500000 | DF20: MoviCentralSupply Chain Management | DG20: 1666666.7 | DH20: DNG | DI20: =IFERROR(VLOOKUP($B20,[1]Timesheet!$D:$BK,51,0),0) -> 22 | DJ20: =IFERROR(VLOOKUP($B20,[1]Timesheet!$D:$BK,52,0),0) -> 0 | DK20: =IFERROR(VLOOKUP($B20,[1]Timesheet!$D:$BK,55,0),0) -> 0 | DL20: x | DM20: =IFERROR(VLOOKUP($B20,[1]Timesheet!$D:$BK,57,0),0) -> 0 | DN20: =IF(AND(DL20="x",CB20>0),MIN(ROUND(W20*1%,0),149000),0) -> 149000 | DP20: =IF(E20="Sales",IF(F20="Logistics",F20,IF(F20="Marketing",F20,DH20)),"") | DQ20: 0 | DR20: 0 | DS20: =IFERROR(VLOOKUP(E20&H20,[1]Group!$D$3:$G$40,4,0),"") -> Group 4 | DT20: =J20&I20&DS20 -> MoviCentralGroup 4
A21: 18 | B21: 3338 | C21: MV003338 | D21: Nguyễn Thanh Nhàn | E21: Supply Chain Management | F21: Logistics | G21: Assistant Manager | H21: Assistant to Supply Chain Manager | I21: South | J21: Movi | K21: Full-time | L21: Permanent | M21: 42650 | Q21: LC | R21: LTTP | S21: L | U21: 30000000 | W21: 30000000 | X21: 0 | Y21: 0 | AA21: 200000 | AC21: 0 | AD21: 200000 | AE21: CN | AF21: 26 | AG21: 26 | AH21: 0 | AI21: 0 | AJ21: 0 | AK21: 26 | AL21: 0 | AM21: 0 | AN21: 0 | AO21: 0 | AP21: 0 | AQ21: 0 | AR21: 30000000 | AS21: 0 | AT21: 0 | AU21: 30000000 | AV21: 0 | AW21: 0 | AX21: 0 | AY21: 200000 | AZ21: 0 | BA21: 0 | BE21: 0 | BF21: 200000 | BG21: 0 | BH21: 0 | BI21: 0 | BJ21: 0 | BL21: 0 | BO21: 0 | BT21: 0 | BU21: 30200000 | BV21: 0 | BW21: 200000 | BX21: 0 | BY21: 11000000 | BZ21: 0 | CA21: 0 | CB21: 2384000 | CC21: 300000 | CD21: 447000 | CE21: 0 | CF21: 3131000 | CG21: 14331000 | CH21: 15869000 | CI21: 1630350 | CK21: 1630350 | CL21: 0 | CM21: 149000 | CN21: 0 | CP21: 0 | CQ21: 0 | CR21: 149000 | CS21: 25289650 | CU21: 25289650 | CV21: 5066000 | CW21: 0 | CX21: 894000 | CY21: 0 | DA21: 5960000 | DB21: 9091000 | DC21: 596000 | DD21: 36756000 | DF21: MoviSouthSupply Chain Management | DG21: 2500000 | DH21: MKD | DI21: =IFERROR(VLOOKUP($B21,[1]Timesheet!$D:$BK,51,0),0) -> 22 | DJ21: =IFERROR(VLOOKUP($B21,[1]Timesheet!$D:$BK,52,0),0) -> 0 | DK21: =IFERROR(VLOOKUP($B21,[1]Timesheet!$D:$BK,55,0),0) -> 0 | DL21: x | DM21: =IFERROR(VLOOKUP($B21,[1]Timesheet!$D:$BK,57,0),0) -> 0 | DN21: =IF(AND(DL21="x",CB21>0),MIN(ROUND(W21*1%,0),149000),0) -> 149000 | DP21: =IF(E21="Sales",IF(F21="Logistics",F21,IF(F21="Marketing",F21,DH21)),"") | DQ21: 0 | DR21: 0 | DS21: =IFERROR(VLOOKUP(E21&H21,[1]Group!$D$3:$G$40,4,0),"") | DT21: =J21&I21&DS21 -> MoviSouth
A22: 19 | B22: 1853 | C22: MV001853 | D22: Trần Thị Trang | E22: Supply Chain Management | F22: Logistics | G22: Supervisor | H22: Logistics Supervisor | I22: North | J22: Movi | K22: Full-time | L22: Permanent | M22: 42137 | Q22: LC | R22: LTTP | S22: L | U22: 20000000 | W22: 20000000 | X22: 0 | Y22: 0 | AA22: 200000 | AC22: 0 | AD22: 200000 | AE22: CN | AF22: 26 | AG22: 26 | AH22: 0 | AI22: 0 | AJ22: 0 | AK22: 26 | AL22: 0 | AM22: 0 | AN22: 0 | AO22: 0 | AP22: 0 | AQ22: 0 | AR22: 20000000 | AS22: 0 | AT22: 0 | AU22: 20000000 | AV22: 0 | AW22: 0 | AX22: 0 | AY22: 200000 | AZ22: 0 | BA22: 0 | BE22: 0 | BF22: 200000 | BG22: 0 | BH22: 0 | BI22: 0 | BJ22: 0 | BL22: 0 | BO22: 0 | BT22: 0 | BU22: 20200000 | BV22: 0 | BW22: 200000 | BX22: 0 | BY22: 11000000 | BZ22: 1 | CA22: 4400000 | CB22: 1600000 | CC22: 200000 | CD22: 300000 | CE22: 0 | CF22: 2100000 | CG22: 17700000 | CH22: 2500000 | CI22: 125000 | CK22: 125000 | CL22: 0 | CM22: 149000 | CN22: 0 | CP22: 1459000 | CQ22: 0 | CR22: 1608000 | CS22: 16367000 | CU22: 16367000 | CV22: 3400000 | CW22: 0 | CX22: 600000 | CY22: 0 | DA22: 4000000 | DB22: 6100000 | DC22: 400000 | DD22: 24600000 | DF22: MoviNorthSupply Chain Management | DG22: 1666666.7 | DH22: HNI | DI22: =IFERROR(VLOOKUP($B22,[1]Timesheet!$D:$BK,51,0),0) -> 22 | DJ22: =IFERROR(VLOOKUP($B22,[1]Timesheet!$D:$BK,52,0),0) -> 0 | DK22: =IFERROR(VLOOKUP($B22,[1]Timesheet!$D:$BK,55,0),0) -> 0 | DL22: x | DM22: =IFERROR(VLOOKUP($B22,[1]Timesheet!$D:$BK,57,0),0) -> 0 | DN22: =IF(AND(DL22="x",CB22>0),MIN(ROUND(W22*1%,0),149000),0) -> 149000 | DP22: =IF(E22="Sales",IF(F22="Logistics",F22,IF(F22="Marketing",F22,DH22)),"") | DQ22: 0 | DR22: 0 | DS22: =IFERROR(VLOOKUP(E22&H22,[1]Group!$D$3:$G$40,4,0),"") -> Group 4 | DT22: =J22&I22&DS22 -> MoviNorthGroup 4
A23: 20 | B23: 4065 | C23: MV004065 | D23: Nguyễn Thị Ngọc Yến | E23: Supply Chain Management | F23: Logistics | G23: Supervisor | H23: Logistics Supervisor | I23: South | J23: Movi | K23: Full-time | L23: Permanent | M23: 43054 | Q23: LC | R23: LTTP | S23: L | U23: 20000000 | W23: 20000000 | X23: 0 | Y23: 0 | AA23: 200000 | AC23: 0 | AD23: 200000 | AE23: CN | AF23: 26 | AG23: 26 | AH23: 0 | AI23: 0 | AJ23: 0 | AK23: 26 | AL23: 0 | AM23: 0 | AN23: 0 | AO23: 0 | AP23: 0 | AQ23: 0 | AR23: 20000000 | AS23: 0 | AT23: 0 | AU23: 20000000 | AV23: 0 | AW23: 0 | AX23: 0 | AY23: 200000 | AZ23: 0 | BA23: 0 | BE23: 0 | BF23: 200000 | BG23: 0 | BH23: 0 | BI23: 0 | BJ23: 0 | BL23: 0 | BO23: 0 | BT23: 0 | BU23: 20200000 | BV23: 0 | BW23: 200000 | BX23: 0 | BY23: 11000000 | BZ23: 0 | CA23: 0 | CB23: 1600000 | CC23: 200000 | CD23: 300000 | CE23: 0 | CF23: 2100000 | CG23: 13300000 | CH23: 6900000 | CI23: 440000 | CK23: 440000 | CL23: 0 | CM23: 149000 | CN23: 0 | CP23: 0 | CQ23: 0 | CR23: 149000 | CS23: 17511000 | CU23: 17511000 | CV23: 3400000 | CW23: 0 | CX23: 600000 | CY23: 0 | DA23: 4000000 | DB23: 6100000 | DC23: 400000 | DD23: 24600000 | DF23: MoviSouthSupply Chain Management | DG23: 1666666.7 | DH23: MKD | DI23: =IFERROR(VLOOKUP($B23,[1]Timesheet!$D:$BK,51,0),0) -> 22 | DJ23: =IFERROR(VLOOKUP($B23,[1]Timesheet!$D:$BK,52,0),0) -> 0 | DK23: =IFERROR(VLOOKUP($B23,[1]Timesheet!$D:$BK,55,0),0) -> 0 | DL23: x | DM23: =IFERROR(VLOOKUP($B23,[1]Timesheet!$D:$BK,57,0),0) -> 0 | DN23: =IF(AND(DL23="x",CB23>0),MIN(ROUND(W23*1%,0),149000),0) -> 149000 | DP23: =IF(E23="Sales",IF(F23="Logistics",F23,IF(F23="Marketing",F23,DH23)),"") | DQ23: 0 | DR23: 0 | DS23: =IFERROR(VLOOKUP(E23&H23,[1]Group!$D$3:$G$40,4,0),"") -> Group 4 | DT23: =J23&I23&DS23 -> MoviSouthGroup 4
A24: 21 | B24: 2503 | C24: MV002503 | D24: Ngô Thị Phương Thảo | E24: Sales | F24: Field Sales | G24: Associate | H24: Field sales | I24: South | J24: Movi | K24: Full-time | L24: Permanent | M24: 42191 | Q24: LC | R24: LTTP | S24: L | U24: 5000000 | W24: 5000000 | X24: 0 | Y24: 0 | AA24: 200000 | AC24: 730000 | AD24: 930000 | AE24: CN | AF24: 26 | AG24: 24.5 | AH24: 1.5 | AI24: 0 | AJ24: 0 | AK24: 26 | AL24: 0 | AM24: 0 | AN24: 0 | AO24: 0 | AP24: 0 | AQ24: 0 | AR24: 5000000 | AS24: 0 | AT24: 0 | AU24: 5000000 | AV24: 0 | AW24: 0 | AX24: 0 | AY24: 200000 | AZ24: 0 | BA24: 0 | BE24: 687885 | BF24: 887885 | BG24: 0 | BH24: 0 | BI24: 0 | BJ24: 0 | BL24: 0 | BO24: 0 | BT24: 0 | BU24: 5887885 | BV24: 0 | BW24: 200000 | BX24: 687885 | BY24: 11000000 | BZ24: 0 | CA24: 0 | CB24: 400000 | CC24: 50000 | CD24: 75000 | CE24: 0 | CF24: 525000 | CG24: 12412885 | CH24: 0 | CI24: 0 | CK24: 0 | CL24: 0 | CM24: 50000 | CN24: 0 | CP24: 594000 | CQ24: 0 | CR24: 644000 | CS24: 4718885 | CU24: 4718885 | CV24: 850000 | CW24: 0 | CX24: 150000 | CY24: 0 | DA24: 1000000 | DB24: 1525000 | DC24: 100000 | DD24: 6987885 | DF24: MoviSouthSales | DG24: 416666.67 | DH24: DNI | DI24: =IFERROR(VLOOKUP($B24,[1]Timesheet!$D:$BK,51,0),0) -> 22 | DJ24: =IFERROR(VLOOKUP($B24,[1]Timesheet!$D:$BK,52,0),0) -> 0 | DK24: =IFERROR(VLOOKUP($B24,[1]Timesheet!$D:$BK,55,0),0) -> 0 | DL24: x | DM24: =IFERROR(VLOOKUP($B24,[1]Timesheet!$D:$BK,57,0),0) -> 0 | DN24: =IF(AND(DL24="x",CB24>0),MIN(ROUND(W24*1%,0),149000),0) -> 50000 | DP24: =IF(E24="Sales",IF(F24="Logistics",F24,IF(F24="Marketing",F24,DH24)),"") -> DNI | DQ24: 0 | DR24: 0 | DS24: =IFERROR(VLOOKUP(E24&H24,[1]Group!$D$3:$G$40,4,0),"") -> Group 1 | DT24: =J24&I24&DS24 -> MoviSouthGroup 1
A25: 22 | B25: 3633 | C25: MV003633 | D25: Nguyễn Minh Kha | E25: Supply Chain Management | F25: Logistics | G25: Associate | H25: Logistics Officer | I25: South | J25: Movi | K25: Full-time | L25: Leaving | M25: 42898 | P25: 44532 | Q25: LC | R25: LTTP | S25: L | U25: 5000000 | W25: 5000000 | X25: 0 | Y25: 0 | AA25: 100000 | AC25: 0 | AD25: 100000 | AE25: CN | AF25: 26 | AG25: 5 | AH25: 0 | AI25: 0 | AJ25: 0 | AK25: 5 | AL25: 0 | AM25: 0 | AN25: 0 | AO25: 0 | AP25: 0 | AQ25: 0 | AR25: 961538 | AS25: 1076923 | AT25: 0 | AU25: 2038461 | AV25: 0 | AW25: 0 | AX25: 0 | AY25: 50000 | AZ25: 0 | BA25: 0 | BE25: 0 | BF25: 50000 | BG25: 0 | BH25: 0 | BI25: 0 | BJ25: 0 | BL25: 0 | BO25: 0 | BT25: 0 | BU25: 2088461 | BV25: 0 | BW25: 50000 | BX25: 0 | BY25: 11000000 | BZ25: 0 | CA25: 0 | CB25: 0 | CC25: 0 | CD25: 0 | CE25: 0 | CF25: 0 | CG25: 11050000 | CH25: 0 | CI25: 0 | CK25: 0 | CL25: 0 | CM25: 0 | CN25: 0 | CP25: 0 | CQ25: 0 | CR25: 0 | CS25: 2088461 | CU25: 2088461 | CV25: 0 | CW25: 0 | CX25: 0 | CY25: 0 | DA25: 0 | DB25: 0 | DC25: 0 | DD25: 2088461 | DF25: MoviSouthSupply Chain Management | DG25: 416666.67 | DH25: DNI | DI25: =IFERROR(VLOOKUP($B25,[1]Timesheet!$D:$BK,51,0),0) -> 1 | DJ25: =IFERROR(VLOOKUP($B25,[1]Timesheet!$D:$BK,52,0),0) -> 0 | DK25: =IFERROR(VLOOKUP($B25,[1]Timesheet!$D:$BK,55,0),0) -> 0 | DL25: 0 | DM25: =IFERROR(VLOOKUP($B25,[1]Timesheet!$D:$BK,57,0),0) -> 0 | DN25: =IF(AND(DL25="x",CB25>0),MIN(ROUND(W25*1%,0),149000),0) -> 0 | DP25: =IF(E25="Sales",IF(F25="Logistics",F25,IF(F25="Marketing",F25,DH25)),"") | DQ25: 0 | DR25: 0 | DS25: =IFERROR(VLOOKUP(E25&H25,[1]Group!$D$3:$G$40,4,0),"") -> Group 4 | DT25: =J25&I25&DS25 -> MoviSouthGroup 4
A26: 23 | B26: 2745 | C26: MV002745 | D26: Lê Đăng Hiệu | E26: Supply Chain Management | F26: Logistics | G26: Associate | H26: Logistics Officer | I26: South | J26: Movi | K26: Full-time | L26: Permanent | M26: 42338 | Q26: LC | R26: LTTP | S26: L | U26: 5000000 | W26: 5000000 | X26: 0 | Y26: 0 | AA26: 200000 | AC26: 0 | AD26: 200000 | AE26: CN | AF26: 26 | AG26: 26 | AH26: 0 | AI26: 0 | AJ26: 0 | AK26: 26 | AL26: 0 | AM26: 0 | AN26: 0 | AO26: 0 | AP26: 0 | AQ26: 0 | AR26: 5000000 | AS26: 0 | AT26: 0 | AU26: 5000000 | AV26: 0 | AW26: 0 | AX26: 0 | AY26: 200000 | AZ26: 0 | BA26: 0 | BE26: 0 | BF26: 200000 | BG26: 0 | BH26: 0 | BI26: 0 | BJ26: 0 | BL26: 0 | BO26: 0 | BT26: 0 | BU26: 5200000 | BV26: 0 | BW26: 200000 | BX26: 0 | BY26: 11000000 | BZ26: 0 | CA26: 0 | CB26: 400000 | CC26: 50000 | CD26: 75000 | CE26: 0 | CF26: 525000 | CG26: 11725000 | CH26: 0 | CI26: 0 | CK26: 0 | CL26: 0 | CM26: 50000 | CN26: 0 | CP26: 3179000 | CQ26: 0 | CR26: 3229000 | CS26: 1446000 | CU26: 1446000 | CV26: 850000 | CW26: 0 | CX26: 150000 | CY26: 0 | DA26: 1000000 | DB26: 1525000 | DC26: 100000 | DD26: 6300000 | DF26: MoviSouthSupply Chain Management | DG26: 416666.67 | DH26: HCM | DI26: =IFERROR(VLOOKUP($B26,[1]Timesheet!$D:$BK,51,0),0) -> 22 | DJ26: =IFERROR(VLOOKUP($B26,[1]Timesheet!$D:$BK,52,0),0) -> 0 | DK26: =IFERROR(VLOOKUP($B26,[1]Timesheet!$D:$BK,55,0),0) -> 0 | DL26: x | DM26: =IFERROR(VLOOKUP($B26,[1]Timesheet!$D:$BK,57,0),0) -> 0 | DN26: =IF(AND(DL26="x",CB26>0),MIN(ROUND(W26*1%,0),149000),0) -> 50000 | DP26: =IF(E26="Sales",IF(F26="Logistics",F26,IF(F26="Marketing",F26,DH26)),"") | DQ26: 0 | DR26: 0 | DS26: =IFERROR(VLOOKUP(E26&H26,[1]Group!$D$3:$G$40,4,0),"") -> Group 4 | DT26: =J26&I26&DS26 -> MoviSouthGroup 4
A27: 24 | B27: 5056 | C27: MV005056 | D27: Nguyễn Văn Việt | E27: Supply Chain Management | F27: Logistics | G27: Associate | H27: Logistics Officer | I27: South | J27: Movi | K27: Full-time | L27: Permanent | M27: 43616 | Q27: LC | R27: LTTP | S27: L | U27: 5000000 | W27: 5000000 | X27: 0 | Y27: 0 | AA27: 0 | AC27: 0 | AD27: 0 | AE27: CN | AF27: 26 | AG27: 26 | AH27: 0 | AI27: 0 | AJ27: 0 | AK27: 26 | AL27: 0 | AM27: 0 | AN27: 0 | AO27: 0 | AP27: 0 | AQ27: 0 | AR27: 5000000 | AS27: 0 | AT27: 0 | AU27: 5000000 | AV27: 0 | AW27: 0 | AX27: 0 | AY27: 0 | AZ27: 0 | BA27: 0 | BE27: 0 | BF27: 0 | BG27: 0 | BH27: 0 | BI27: 0 | BJ27: 0 | BL27: 0 | BO27: 0 | BT27: 0 | BU27: 5000000 | BV27: 0 | BW27: 0 | BX27: 0 | BY27: 11000000 | BZ27: 0 | CA27: 0 | CB27: 400000 | CC27: 50000 | CD27: 75000 | CE27: 0 | CF27: 525000 | CG27: 11525000 | CH27: 0 | CI27: 0 | CK27: 0 | CL27: 0 | CM27: 0 | CN27: 0 | CP27: 0 | CQ27: 0 | CR27: 0 | CS27: 4475000 | CU27: 4475000 | CV27: 850000 | CW27: 0 | CX27: 150000 | CY27: 0 | DA27: 1000000 | DB27: 1525000 | DC27: 100000 | DD27: 6100000 | DF27: MoviSouthSupply Chain Management | DG27: 416666.67 | DH27: MKD | DI27: =IFERROR(VLOOKUP($B27,[1]Timesheet!$D:$BK,51,0),0) -> 22 | DJ27: =IFERROR(VLOOKUP($B27,[1]Timesheet!$D:$BK,52,0),0) -> 0 | DK27: =IFERROR(VLOOKUP($B27,[1]Timesheet!$D:$BK,55,0),0) -> 0 | DL27: 0 | DM27: =IFERROR(VLOOKUP($B27,[1]Timesheet!$D:$BK,57,0),0) -> 0 | DN27: =IF(AND(DL27="x",CB27>0),MIN(ROUND(W27*1%,0),149000),0) -> 0 | DP27: =IF(E27="Sales",IF(F27="Logistics",F27,IF(F27="Marketing",F27,DH27)),"") | DQ27: 0 | DR27: 0 | DS27: =IFERROR(VLOOKUP(E27&H27,[1]Group!$D$3:$G$40,4,0),"") -> Group 4 | DT27: =J27&I27&DS27 -> MoviSouthGroup 4
A28: 25 | B28: 5107 | C28: MV005107 | D28: Hồ Trung Tín | E28: Supply Chain Management | F28: Logistics | G28: Supervisor | H28: Logistics Supervisor | I28: South | J28: Movi | K28: Full-time | L28: Permanent | M28: 43642 | Q28: LC | R28: LTTP | S28: L | U28: 20000000 | W28: 20000000 | X28: 0 | Y28: 0 | AA28: 200000 | AC28: 0 | AD28: 200000 | AE28: CN | AF28: 26 | AG28: 26 | AH28: 0 | AI28: 0 | AJ28: 0 | AK28: 26 | AL28: 0 | AM28: 0 | AN28: 0 | AO28: 0 | AP28: 0 | AQ28: 0 | AR28: 20000000 | AS28: 0 | AT28: 0 | AU28: 20000000 | AV28: 0 | AW28: 0 | AX28: 0 | AY28: 200000 | AZ28: 0 | BA28: 0 | BE28: 0 | BF28: 200000 | BG28: 0 | BH28: 0 | BI28: 0 | BJ28: 0 | BL28: 0 | BO28: 0 | BT28: 0 | BU28: 20200000 | BV28: 0 | BW28: 200000 | BX28: 0 | BY28: 11000000 | BZ28: 0 | CA28: 0 | CB28: 1600000 | CC28: 200000 | CD28: 300000 | CE28: 0 | CF28: 2100000 | CG28: 13300000 | CH28: 6900000 | CI28: 440000 | CK28: 440000 | CL28: 0 | CM28: 0 | CN28: 0 | CP28: 0 | CQ28: 0 | CR28: 0 | CS28: 17660000 | CU28: 17660000 | CV28: 3400000 | CW28: 0 | CX28: 600000 | CY28: 0 | DA28: 4000000 | DB28: 6100000 | DC28: 400000 | DD28: 24600000 | DF28: MoviSouthSupply Chain Management | DG28: 1666666.7 | DH28: BDG | DI28: =IFERROR(VLOOKUP($B28,[1]Timesheet!$D:$BK,51,0),0) -> 22 | DJ28: =IFERROR(VLOOKUP($B28,[1]Timesheet!$D:$BK,52,0),0) -> 0 | DK28: =IFERROR(VLOOKUP($B28,[1]Timesheet!$D:$BK,55,0),0) -> 0 | DL28: 0 | DM28: =IFERROR(VLOOKUP($B28,[1]Timesheet!$D:$BK,57,0),0) -> 0 | DN28: =IF(AND(DL28="x",CB28>0),MIN(ROUND(W28*1%,0),149000),0) -> 0 | DP28: =IF(E28="Sales",IF(F28="Logistics",F28,IF(F28="Marketing",F28,DH28)),"") | DQ28: 0 | DR28: 0 | DS28: =IFERROR(VLOOKUP(E28&H28,[1]Group!$D$3:$G$40,4,0),"") -> Group 4 | DT28: =J28&I28&DS28 -> MoviSouthGroup 4
A29: 26 | B29: 2536 | C29: MV002536 | D29: Đào Tuấn Anh | E29: Supply Chain Management | F29: Logistics | G29: Associate | H29: Delivery Man | I29: North | J29: Movi | K29: Full-time | L29: Permanent | M29: 42255 | Q29: LC | R29: LTTP | S29: L | U29: 5000000 | W29: 5000000 | X29: 0 | Y29: 0 | AA29: 100000 | AC29: 0 | AD29: 100000 | AE29: CN | AF29: 26 | AG29: 26 | AH29: 0 | AI29: 0 | AJ29: 0 | AK29: 26 | AL29: 0 | AM29: 0 | AN29: 0 | AO29: 0 | AP29: 0 | AQ29: 0 | AR29: 5000000 | AS29: 0 | AT29: 0 | AU29: 5000000 | AV29: 0 | AW29: 0 | AX29: 0 | AY29: 100000 | AZ29: 0 | BA29: 0 | BE29: 0 | BF29: 100000 | BG29: 0 | BH29: 0 | BI29: 0 | BJ29: 0 | BL29: 0 | BO29: 0 | BT29: 0 | BU29: 5100000 | BV29: 0 | BW29: 100000 | BX29: 0 | BY29: 11000000 | BZ29: 2 | CA29: 8800000 | CB29: 400000 | CC29: 50000 | CD29: 75000 | CE29: 0 | CF29: 525000 | CG29: 20425000 | CH29: 0 | CI29: 0 | CK29: 0 | CL29: 0 | CM29: 50000 | CN29: 0 | CP29: 0 | CQ29: 0 | CR29: 50000 | CS29: 4525000 | CU29: 4525000 | CV29: 850000 | CW29: 0 | CX29: 150000 | CY29: 0 | DA29: 1000000 | DB29: 1525000 | DC29: 100000 | DD29: 6200000 | DF29: MoviNorthSupply Chain Management | DG29: 416666.67 | DH29: THA | DI29: =IFERROR(VLOOKUP($B29,[1]Timesheet!$D:$BK,51,0),0) -> 22 | DJ29: =IFERROR(VLOOKUP($B29,[1]Timesheet!$D:$BK,52,0),0) -> 0 | DK29: =IFERROR(VLOOKUP($B29,[1]Timesheet!$D:$BK,55,0),0) -> 0 | DL29: x | DM29: =IFERROR(VLOOKUP($B29,[1]Timesheet!$D:$BK,57,0),0) -> 0 | DN29: =IF(AND(DL29="x",CB29>0),MIN(ROUND(W29*1%,0),149000),0) -> 50000 | DP29: =IF(E29="Sales",IF(F29="Logistics",F29,IF(F29="Marketing",F29,DH29)),"") | DQ29: 0 | DR29: 0 | DS29: =IFERROR(VLOOKUP(E29&H29,[1]Group!$D$3:$G$40,4,0),"") -> Group 4 | DT29: =J29&I29&DS29 -> MoviNorthGroup 4
A30: 27 | B30: 2482 | C30: MV002482 | D30: Nguyễn Văn Bình | E30: Supply Chain Management | F30: Logistics | G30: Associate | H30: Delivery man | I30: South | J30: Movi | K30: Full-time | L30: Permanent | M30: 42177 | Q30: LC | R30: LTTP | S30: L | U30: 5000000 | W30: 5000000 | X30: 0 | Y30: 0 | AA30: 100000 | AC30: 0 | AD30: 100000 | AE30: CN | AF30: 26 | AG30: 25 | AH30: 1 | AI30: 0 | AJ30: 0 | AK30: 26 | AL30: 0 | AM30: 0 | AN30: 0 | AO30: 0 | AP30: 0 | AQ30: 0 | AR30: 5000000 | AS30: 0 | AT30: 0 | AU30: 5000000 | AV30: 0 | AW30: 0 | AX30: 0 | AY30: 100000 | AZ30: 0 | BA30: 0 | BE30: 0 | BF30: 100000 | BG30: 0 | BH30: 0 | BI30: 0 | BJ30: 0 | BL30: 0 | BO30: 0 | BT30: 0 | BU30: 5100000 | BV30: 0 | BW30: 100000 | BX30: 0 | BY30: 11000000 | BZ30: 0 | CA30: 0 | CB30: 400000 | CC30: 50000 | CD30: 75000 | CE30: 0 | CF30: 525000 | CG30: 11625000 | CH30: 0 | CI30: 0 | CK30: 0 | CL30: 0 | CM30: 50000 | CN30: 0 | CP30: 1185000 | CQ30: 0 | CR30: 1235000 | CS30: 3340000 | CU30: 3340000 | CV30: 850000 | CW30: 0 | CX30: 150000 | CY30: 0 | DA30: 1000000 | DB30: 1525000 | DC30: 100000 | DD30: 6200000 | DF30: MoviSouthSupply Chain Management | DG30: 416666.67 | DH30: MKD | DI30: =IFERROR(VLOOKUP($B30,[1]Timesheet!$D:$BK,51,0),0) -> 22 | DJ30: =IFERROR(VLOOKUP($B30,[1]Timesheet!$D:$BK,52,0),0) -> 0 | DK30: =IFERROR(VLOOKUP($B30,[1]Timesheet!$D:$BK,55,0),0) -> 0 | DL30: x | DM30: =IFERROR(VLOOKUP($B30,[1]Timesheet!$D:$BK,57,0),0) -> 0 | DN30: =IF(AND(DL30="x",CB30>0),MIN(ROUND(W30*1%,0),149000),0) -> 50000 | DP30: =IF(E30="Sales",IF(F30="Logistics",F30,IF(F30="Marketing",F30,DH30)),"") | DQ30: 0 | DR30: 0 | DS30: =IFERROR(VLOOKUP(E30&H30,[1]Group!$D$3:$G$40,4,0),"") -> Group 4 | DT30: =J30&I30&DS30 -> MoviSouthGroup 4
A31: 28 | B31: 2754 | C31: MV002754 | D31: Huỳnh Tấn Vũ | E31: Supply Chain Management | F31: Logistics | G31: Associate | H31: Delivery man | I31: South | J31: Movi | K31: Full-time | L31: Permanent | M31: 42340 | Q31: LC | R31: LTTP | S31: L | U31: 5000000 | W31: 5000000 | X31: 0 | Y31: 0 | AA31: 100000 | AC31: 0 | AD31: 100000 | AE31: CN | AF31: 26 | AG31: 26 | AH31: 0 | AI31: 0 | AJ31: 0 | AK31: 26 | AL31: 0 | AM31: 0 | AN31: 0 | AO31: 0 | AP31: 0 | AQ31: 0 | AR31: 5000000 | AS31: 0 | AT31: 0 | AU31: 5000000 | AV31: 0 | AW31: 0 | AX31: 0 | AY31: 100000 | AZ31: 0 | BA31: 0 | BE31: 0 | BF31: 100000 | BG31: 0 | BH31: 0 | BI31: 0 | BJ31: 0 | BL31: 0 | BO31: 0 | BT31: 0 | BU31: 5100000 | BV31: 0 | BW31: 100000 | BX31: 0 | BY31: 11000000 | BZ31: 0 | CA31: 0 | CB31: 400000 | CC31: 50000 | CD31: 75000 | CE31: 0 | CF31: 525000 | CG31: 11625000 | CH31: 0 | CI31: 0 | CK31: 0 | CL31: 0 | CM31: 50000 | CN31: 0 | CP31: 1442900 | CQ31: 0 | CR31: 1492900 | CS31: 3082100 | CU31: 3082100 | CV31: 850000 | CW31: 0 | CX31: 150000 | CY31: 0 | DA31: 1000000 | DB31: 1525000 | DC31: 100000 | DD31: 6200000 | DF31: MoviSouthSupply Chain Management | DG31: 416666.67 | DH31: TNH | DI31: =IFERROR(VLOOKUP($B31,[1]Timesheet!$D:$BK,51,0),0) -> 22 | DJ31: =IFERROR(VLOOKUP($B31,[1]Timesheet!$D:$BK,52,0),0) -> 0 | DK31: =IFERROR(VLOOKUP($B31,[1]Timesheet!$D:$BK,55,0),0) -> 0 | DL31: x | DM31: =IFERROR(VLOOKUP($B31,[1]Timesheet!$D:$BK,57,0),0) -> 0 | DN31: =IF(AND(DL31="x",CB31>0),MIN(ROUND(W31*1%,0),149000),0) -> 50000 | DP31: =IF(E31="Sales",IF(F31="Logistics",F31,IF(F31="Marketing",F31,DH31)),"") | DQ31: 0 | DR31: 0 | DS31: =IFERROR(VLOOKUP(E31&H31,[1]Group!$D$3:$G$40,4,0),"") -> Group 4 | DT31: =J31&I31&DS31 -> MoviSouthGroup 4
A32: 29 | B32: 2766 | C32: MV002766 | D32: Nguyễn Thanh Hải | E32: Supply Chain Management | F32: Logistics | G32: Associate | H32: Delivery Man | I32: North | J32: Movi | K32: Full-time | L32: Permanent | M32: 42346 | Q32: LC | R32: LTTP | S32: L | U32: 5000000 | W32: 5000000 | X32: 0 | Y32: 0 | AA32: 100000 | AC32: 0 | AD32: 100000 | AE32: CN | AF32: 26 | AG32: 26 | AH32: 0 | AI32: 0 | AJ32: 0 | AK32: 26 | AL32: 0 | AM32: 0 | AN32: 0 | AO32: 0 | AP32: 0 | AQ32: 0 | AR32: 5000000 | AS32: 0 | AT32: 0 | AU32: 5000000 | AV32: 0 | AW32: 0 | AX32: 0 | AY32: 100000 | AZ32: 0 | BA32: 0 | BE32: 0 | BF32: 100000 | BG32: 0 | BH32: 0 | BI32: 0 | BJ32: 0 | BL32: 0 | BO32: 0 | BT32: 0 | BU32: 5100000 | BV32: 0 | BW32: 100000 | BX32: 0 | BY32: 11000000 | BZ32: 0 | CA32: 0 | CB32: 400000 | CC32: 50000 | CD32: 75000 | CE32: 0 | CF32: 525000 | CG32: 11625000 | CH32: 0 | CI32: 0 | CK32: 0 | CL32: 0 | CM32: 0 | CN32: 0 | CP32: 0 | CQ32: 0 | CR32: 0 | CS32: 4575000 | CU32: 4575000 | CV32: 850000 | CW32: 0 | CX32: 150000 | CY32: 0 | DA32: 1000000 | DB32: 1525000 | DC32: 100000 | DD32: 6200000 | DF32: MoviNorthSupply Chain Management | DG32: 416666.67 | DH32: HPG | DI32: =IFERROR(VLOOKUP($B32,[1]Timesheet!$D:$BK,51,0),0) -> 22 | DJ32: =IFERROR(VLOOKUP($B32,[1]Timesheet!$D:$BK,52,0),0) -> 0 | DK32: =IFERROR(VLOOKUP($B32,[1]Timesheet!$D:$BK,55,0),0) -> 0 | DL32: 0 | DM32: =IFERROR(VLOOKUP($B32,[1]Timesheet!$D:$BK,57,0),0) -> 0 | DN32: =IF(AND(DL32="x",CB32>0),MIN(ROUND(W32*1%,0),149000),0) -> 0 | DP32: =IF(E32="Sales",IF(F32="Logistics",F32,IF(F32="Marketing",F32,DH32)),"") | DQ32: 0 | DR32: 0 | DS32: =IFERROR(VLOOKUP(E32&H32,[1]Group!$D$3:$G$40,4,0),"") -> Group 4 | DT32: =J32&I32&DS32 -> MoviNorthGroup 4
A33: 30 | B33: 4610 | C33: MV004610 | D33: Ngô Công Tuấn Phong | E33: Supply Chain Management | F33: Logistics | G33: Associate | H33: Delivery man | I33: South | J33: Movi | K33: Full-time | L33: Permanent | M33: 43236 | Q33: LC | R33: LTTP | S33: L | U33: 5000000 | W33: 5000000 | X33: 0 | Y33: 0 | AA33: 100000 | AC33: 0 | AD33: 100000 | AE33: CN | AF33: 26 | AG33: 26 | AH33: 0 | AI33: 0 | AJ33: 0 | AK33: 26 | AL33: 0 | AM33: 0 | AN33: 0 | AO33: 0 | AP33: 0 | AQ33: 0 | AR33: 5000000 | AS33: 0 | AT33: 0 | AU33: 5000000 | AV33: 0 | AW33: 0 | AX33: 0 | AY33: 100000 | AZ33: 0 | BA33: 0 | BE33: 0 | BF33: 100000 | BG33: 0 | BH33: 0 | BI33: 0 | BJ33: 0 | BL33: 0 | BO33: 0 | BT33: 0 | BU33: 5100000 | BV33: 0 | BW33: 100000 | BX33: 0 | BY33: 11000000 | BZ33: 0 | CA33: 0 | CB33: 400000 | CC33: 50000 | CD33: 75000 | CE33: 0 | CF33: 525000 | CG33: 11625000 | CH33: 0 | CI33: 0 | CK33: 0 | CL33: 0 | CM33: 0 | CN33: 0 | CP33: 0 | CQ33: 0 | CR33: 0 | CS33: 4575000 | CU33: 4575000 | CV33: 850000 | CW33: 0 | CX33: 150000 | CY33: 0 | DA33: 1000000 | DB33: 1525000 | DC33: 100000 | DD33: 6200000 | DF33: MoviSouthSupply Chain Management | DG33: 416666.67 | DH33: MKD | DI33: =IFERROR(VLOOKUP($B33,[1]Timesheet!$D:$BK,51,0),0) -> 22 | DJ33: =IFERROR(VLOOKUP($B33,[1]Timesheet!$D:$BK,52,0),0) -> 0 | DK33: =IFERROR(VLOOKUP($B33,[1]Timesheet!$D:$BK,55,0),0) -> 0 | DL33: 0 | DM33: =IFERROR(VLOOKUP($B33,[1]Timesheet!$D:$BK,57,0),0) -> 0 | DN33: =IF(AND(DL33="x",CB33>0),MIN(ROUND(W33*1%,0),149000),0) -> 0 | DP33: =IF(E33="Sales",IF(F33="Logistics",F33,IF(F33="Marketing",F33,DH33)),"") | DQ33: 0 | DR33: 0 | DS33: =IFERROR(VLOOKUP(E33&H33,[1]Group!$D$3:$G$40,4,0),"") -> Group 4 | DT33: =J33&I33&DS33 -> MoviSouthGroup 4
A34: 31 | B34: 5373 | C34: MV005373 | D34: Hồ Hữu Đại | E34: Supply Chain Management | F34: Logistics | G34: Associate | H34: Delivery Man | I34: North | J34: Movi | K34: Full-time | L34: Permanent | M34: 43732 | Q34: LC | R34: LTTP | S34: L | U34: 5000000 | W34: 5000000 | X34: 0 | Y34: 0 | AA34: 100000 | AC34: 0 | AD34: 100000 | AE34: CN | AF34: 26 | AG34: 26 | AH34: 0 | AI34: 0 | AJ34: 0 | AK34: 26 | AL34: 0 | AM34: 0 | AN34: 0 | AO34: 0 | AP34: 0 | AQ34: 0 | AR34: 5000000 | AS34: 0 | AT34: 0 | AU34: 5000000 | AV34: 0 | AW34: 0 | AX34: 0 | AY34: 100000 | AZ34: 0 | BA34: 0 | BE34: 0 | BF34: 100000 | BG34: 0 | BH34: 0 | BI34: 0 | BJ34: 0 | BL34: 0 | BO34: 0 | BT34: 0 | BU34: 5100000 | BV34: 0 | BW34: 100000 | BX34: 0 | BY34: 11000000 | BZ34: 0 | CA34: 0 | CB34: 400000 | CC34: 50000 | CD34: 75000 | CE34: 0 | CF34: 525000 | CG34: 11625000 | CH34: 0 | CI34: 0 | CK34: 0 | CL34: 0 | CM34: 0 | CN34: 0 | CP34: 0 | CQ34: 0 | CR34: 0 | CS34: 4575000 | CU34: 4575000 | CV34: 850000 | CW34: 0 | CX34: 150000 | CY34: 0 | DA34: 1000000 | DB34: 1525000 | DC34: 100000 | DD34: 6200000 | DF34: MoviNorthSupply Chain Management | DG34: 416666.67 | DH34: HPG | DI34: =IFERROR(VLOOKUP($B34,[1]Timesheet!$D:$BK,51,0),0) -> 22 | DJ34: =IFERROR(VLOOKUP($B34,[1]Timesheet!$D:$BK,52,0),0) -> 0 | DK34: =IFERROR(VLOOKUP($B34,[1]Timesheet!$D:$BK,55,0),0) -> 0 | DL34: 0 | DM34: =IFERROR(VLOOKUP($B34,[1]Timesheet!$D:$BK,57,0),0) -> 0 | DN34: =IF(AND(DL34="x",CB34>0),MIN(ROUND(W34*1%,0),149000),0) -> 0 | DP34: =IF(E34="Sales",IF(F34="Logistics",F34,IF(F34="Marketing",F34,DH34)),"") | DQ34: 0 | DR34: 0 | DS34: =IFERROR(VLOOKUP(E34&H34,[1]Group!$D$3:$G$40,4,0),"") -> Group 4 | DT34: =J34&I34&DS34 -> MoviNorthGroup 4
A35: 32 | B35: 6106 | C35: MV006106 | D35: Bùi Thị Minh Nguyệt | E35: Supply Chain Management | F35: Logistics | G35: Supervisor | H35: Logistics Supervisor | I35: South | J35: Movi | K35: Full-time | L35: Permanent | M35: 44295 | Q35: LC | R35: LTTP | S35: L | U35: 20000000 | W35: 20000000 | X35: 0 | Y35: 0 | AA35: 200000 | AC35: 0 | AD35: 200000 | AE35: CN | AF35: 26 | AG35: 26 | AH35: 0 | AI35: 0 | AJ35: 0 | AK35: 26 | AL35: 0 | AM35: 0 | AN35: 0 | AO35: 0 | AP35: 0 | AQ35: 0 | AR35: 20000000 | AS35: 0 | AT35: 0 | AU35: 20000000 | AV35: 0 | AW35: 0 | AX35: 0 | AY35: 200000 | AZ35: 0 | BA35: 0 | BE35: 0 | BF35: 200000 | BG35: 0 | BH35: 0 | BI35: 0 | BJ35: 0 | BL35: 0 | BO35: 0 | BT35: 0 | BU35: 20200000 | BV35: 0 | BW35: 200000 | BX35: 0 | BY35: 11000000 | BZ35: 1 | CA35: 4400000 | CB35: 1600000 | CC35: 200000 | CD35: 300000 | CE35: 0 | CF35: 2100000 | CG35: 17700000 | CH35: 2500000 | CI35: 125000 | CK35: 125000 | CL35: 0 | CM35: 149000 | CN35: 0 | CP35: 2982900 | CQ35: 0 | CR35: 3131900 | CS35: 14843100 | CU35: 14843100 | CV35: 3400000 | CW35: 0 | CX35: 600000 | CY35: 0 | DA35: 4000000 | DB35: 6100000 | DC35: 400000 | DD35: 24600000 | DF35: MoviSouthSupply Chain Management | DG35: 1666666.7 | DH35: HCM | DI35: =IFERROR(VLOOKUP($B35,[1]Timesheet!$D:$BK,51,0),0) -> 22 | DJ35: =IFERROR(VLOOKUP($B35,[1]Timesheet!$D:$BK,52,0),0) -> 0 | DK35: =IFERROR(VLOOKUP($B35,[1]Timesheet!$D:$BK,55,0),0) -> 0 | DL35: x | DM35: =IFERROR(VLOOKUP($B35,[1]Timesheet!$D:$BK,57,0),0) -> 0 | DN35: =IF(AND(DL35="x",CB35>0),MIN(ROUND(W35*1%,0),149000),0) -> 149000 | DP35: =IF(E35="Sales",IF(F35="Logistics",F35,IF(F35="Marketing",F35,DH35)),"") | DQ35: 0 | DR35: 0 | DS35: =IFERROR(VLOOKUP(E35&H35,[1]Group!$D$3:$G$40,4,0),"") -> Group 4 | DT35: =J35&I35&DS35 -> MoviSouthGroup 4
A36: 33 | B36: 1250 | C36: MV001250 | D36: Lê Xuân Hoàng Minh | E36: Supply Chain Management | F36: Merchandise | G36: Manager | H36: Manager, Merchandise | I36: South | J36: Movi | K36: Full-time | L36: Permanent | M36: 40735 | Q36: LC | R36: LTTP | S36: L | U36: 40000000 | W36: 40000000 | X36: 0 | Y36: 0 | AA36: 0 | AC36: 0 | AD36: 0 | AE36: TB, CN | AF36: 21 | AG36: 21 | AH36: 0 | AI36: 0 | AJ36: 0 | AK36: 21 | AL36: 0 | AM36: 0 | AN36: 0 | AO36: 0 | AP36: 0 | AQ36: 0 | AR36: 40000000 | AS36: 0 | AT36: 0 | AU36: 40000000 | AV36: 0 | AW36: 0 | AX36: 0 | AY36: 0 | AZ36: 0 | BA36: 0 | BE36: 0 | BF36: 0 | BG36: 0 | BH36: 0 | BI36: 0 | BJ36: 0 | BL36: 0 | BO36: 0 | BT36: 0 | BU36: 40000000 | BV36: 0 | BW36: 0 | BX36: 0 | BY36: 11000000 | BZ36: 3 | CA36: 13200000 | CB36: 2384000 | CC36: 400000 | CD36: 447000 | CE36: 0 | CF36: 3231000 | CG36: 27431000 | CH36: 12569000 | CI36: 1135350 | CK36: 1135350 | CL36: 0 | CM36: 149000 | CN36: 0 | CP36: 344000 | CQ36: 0 | CR36: 493000 | CS36: 35140650 | CU36: 35140650 | CV36: 5066000 | CW36: 0 | CX36: 894000 | CY36: 0 | DA36: 5960000 | DB36: 9191000 | DC36: 596000 | DD36: 46556000 | DF36: MoviSouthSupply Chain Management | DG36: 3333333.3 | DH36: HO | DI36: =IFERROR(VLOOKUP($B36,[1]Timesheet!$D:$BK,51,0),0) -> 18 | DJ36: =IFERROR(VLOOKUP($B36,[1]Timesheet!$D:$BK,52,0),0) -> 0 | DK36: =IFERROR(VLOOKUP($B36,[1]Timesheet!$D:$BK,55,0),0) -> 0 | DL36: x | DM36: =IFERROR(VLOOKUP($B36,[1]Timesheet!$D:$BK,57,0),0) -> 0 | DN36: =IF(AND(DL36="x",CB36>0),MIN(ROUND(W36*1%,0),149000),0) -> 149000 | DP36: =IF(E36="Sales",IF(F36="Logistics",F36,IF(F36="Marketing",F36,DH36)),"") | DQ36: 0 | DR36: 0 | DS36: =IFERROR(VLOOKUP(E36&H36,[1]Group!$D$3:$G$40,4,0),"") | DT36: =J36&I36&DS36 -> MoviSouth
